<?xml version="1.0" encoding="utf-8"?>

<robot name="horiokart_v2">
  <!-- =============== Link & Joint =============== -->
  <!-- Base -->
  <link name="base_footprint"/>

  <joint name="base_link_joint" type="fixed">
    <origin xyz="0 0 0.20316" rpy="0 0 0"/>
    <parent link="base_footprint"/>
    <child link="base_link"/>
  </joint>
  <link name="base_link">
    <visual>
      <geometry>
        <mesh filename="package://fourth_robot_description/meshes/DAE/base/base_link.dae"/>
      </geometry>
    </visual>
    <collision>
      <geometry>
        <mesh filename="package://fourth_robot_description/meshes/STL/base/base_link.stl"/>
      </geometry>
    </collision>
    <inertial>
      <origin xyz="-0.061 0 -0.002"/>
      <mass value="45"/>
      <inertia ixx="1.64890" ixy="0" ixz="-0.21424" iyy="2.24766" iyz="0" izz="1.25664"/>
    </inertial>
  </link>

  <joint name="right_wheel_joint" type="continuous">
    <origin xyz="0 -0.214375 0"/>
    <axis xyz="0 1 0"/>
    <parent link="base_link"/>
    <child link="right_wheel_link"/>
  </joint>
  <link name="right_wheel_link">
    <visual>
      <geometry>
        <mesh filename="package://fourth_robot_description/meshes/DAE/wheel/wheel_link.dae"/>
      </geometry>
    </visual>
    <collision>
      <origin rpy="-1.57079637 0 0" xyz="0 -0.003 0"/>
      <geometry>
        <cylinder length="0.032" radius="0.20316"/>
      </geometry>
    </collision>
    <inertial>
      <origin rpy="-1.57079637 0 0" xyz="0 -0.003 0"/>
      <mass value="2.0"/>
      <inertia ixx="0.0208076594667" ixy="0" ixz="0" iyy="0.0208076594667" iyz="0" izz="0.0412739856"/>
    </inertial>
  </link>

  <joint name="left_wheel_joint" type="continuous">
    <origin rpy="0 0 3.14159274" xyz="0 0.214375 0"/>
    <axis xyz="0 -1 0"/>
    <parent link="base_link"/>
    <child link="left_wheel_link"/>
  </joint>
  <link name="left_wheel_link">
    <visual>
      <geometry>
        <mesh filename="package://fourth_robot_description/meshes/DAE/wheel/wheel_link.dae"/>
      </geometry>
    </visual>
    <collision>
      <origin rpy="-1.57079637 0 0" xyz="0 -0.003 0"/>
      <geometry>
        <cylinder length="0.032" radius="0.20316"/>
      </geometry>
    </collision>
    <inertial>
      <origin rpy="-1.57079637 0 0" xyz="0 -0.003 0"/>
      <mass value="2.0"/>
      <inertia ixx="0.0208076594667" ixy="0" ixz="0" iyy="0.0208076594667" iyz="0" izz="0.0412739856"/>
    </inertial>
  </link>

  <joint name="front_lrf_link_joint" type="fixed">
    <parent link="base_link"/>
    <child link="front_lrf_link"/>
    <origin xyz="0.31 0 0.15" rpy="0 0 3.14"/>
  </joint>
  <link name="front_lrf_link">
    <visual>
      <geometry>
        <mesh filename="package://fourth_robot_description/meshes/DAE/sensors/front_lrf/front_lrf.dae"/>
      </geometry>
    </visual>
    <collision>
      <geometry>
        <mesh filename="package://fourth_robot_description/meshes/STL/sensors/front_lrf/front_lrf.stl"/>
      </geometry>
    </collision>
    <inertial>
      <origin xyz="0 0 -0.0164"/>
      <mass value="0.4"/>
      <inertia ixx="0.000376666666667" ixy="0" ixz="0" iyy="0.000376666666667" iyz="0" izz="0.000326666666667"/>
    </inertial>
  </link>

  <joint name="gps_link_joint" type="fixed">
    <parent link="base_link"/>
    <child link="gps_link"/>
    <origin xyz="0.15 0 0.33" rpy="0 0 0"/>
  </joint>
  <link name="gps_link">
    <visual>
      <geometry>
        <cylinder length="0.05" radius="0.05"/>
      </geometry>
    </visual>
  </link>

  <joint name="top_link_joint" type="fixed">
    <origin xyz="0.31 0 0.3" rpy="0 0 0"/>
    <parent link="base_link"/>
    <child link="top_link"/>
  </joint>
  <link name="top_link">
    <visual>
      <origin xyz="0 0 0"/>
      <geometry>
        <box size="0.03 0.3 0.03"/>
      </geometry>
    </visual>
  </link>

  <joint name="top_lrf_link_joint" type="fixed">
    <parent link="top_link"/>
    <child link="top_lrf_link"/>
    <origin xyz="0 0 0.03" rpy="0 0 3.14"/>
  </joint>
  <link name="top_lrf_link">
    <visual>
      <geometry>
        <mesh filename="package://fourth_robot_description/meshes/DAE/sensors/front_lrf/front_lrf.dae"/>
      </geometry>
    </visual>
    <collision>
      <geometry>
        <mesh filename="package://fourth_robot_description/meshes/STL/sensors/front_lrf/front_lrf.stl"/>
      </geometry>
    </collision>
    <inertial>
      <origin xyz="0 0 -0.0164"/>
      <mass value="0.4"/>
      <inertia ixx="0.000376666666667" ixy="0" ixz="0" iyy="0.000376666666667" iyz="0" izz="0.000326666666667"/>
    </inertial>
  </link>

  <joint name="rs_d435i_link_joint" type="fixed">
    <parent link="top_link"/>
    <child link="rs_d435i_link"/>
    <origin xyz="0.01 0 -0.01" rpy="0 0 0"/>
  </joint>
  <link name="rs_d435i_link">
    <visual>
      <origin xyz="0 0 0" rpy="0 0 0"/>
      <geometry>
        <box size="0.02 0.05 0.02"/>
      </geometry>
    </visual>
  </link>

  <joint name="rs_d435_link_joint" type="fixed">
    <parent link="top_link"/>
    <child link="rs_d435_link"/>
    <origin xyz="0.01 0 -0.02" rpy="0 0.35 0"/>
  </joint>
  <link name="rs_d435_link">
    <visual>
      <origin xyz="0 0 0" rpy="0 0 0"/>
      <geometry>
        <box size="0.02 0.05 0.02"/>
      </geometry>
    </visual>
  </link>


  <!-- =============== Gazebo =============== -->
  <gazebo>
    <plugin filename="libgazebo_ros_control.so" name="gazebo_ros_control">
      <!-- <robotNamespace>fourth_robot</robotNamespace> -->
    </plugin>
  </gazebo>
  <gazebo reference="base_link">
    <selfCollide>false</selfCollide>
    <mu1 value="0.05"/>
    <mu2 value="0.05"/>
  </gazebo>
  <gazebo reference="right_wheel_link">
    <selfCollide>false</selfCollide>
    <mu1 value="0.8"/>
    <mu2 value="0.8"/>
  </gazebo>
  <gazebo reference="left_wheel_link">
    <selfCollide>false</selfCollide>
    <mu1 value="0.8"/>
    <mu2 value="0.8"/>
  </gazebo>
  <!-- <xacro:wheel_gazebo_control_v0 rate="25"/> -->
  <gazebo reference="front_lrf_link">
    <sensor name="front_lrf_sensor" type="ray">
      <pose>0 0 0 0 0 0</pose>
      <visualize>true</visualize>
      <update_rate>40</update_rate>
      <ray>
        <scan>
          <horizontal>
            <samples>720</samples>
            <resolution>1</resolution>
            <min_angle>-1.65806278939</min_angle>
            <max_angle>1.65806278939</max_angle>
          </horizontal>
        </scan>
        <range>
          <min>0.1</min>
          <max>60.0</max>
          <resolution>0.01</resolution>
        </range>
        <noise>
          <type>gaussian</type>
          <mean>0.0</mean>
          <stddev>0.03</stddev>
        </noise>
      </ray>
      <plugin filename="libgazebo_ros_laser.so" name="gazebo_ros_front_lrf_controller">
        <topicName>front/scan</topicName>
        <frameName>front_lrf_link</frameName>
      </plugin>
    </sensor>
  </gazebo>
  <gazebo reference="rear_lrf_link">
    <sensor name="rear_lrf_sensor" type="ray">
      <pose>0 0 0 0 0 0</pose>
      <visualize>true</visualize>
      <update_rate>40</update_rate>
      <ray>
        <scan>
          <horizontal>
            <samples>720</samples>
            <resolution>1</resolution>
            <min_angle>-2.35619449019</min_angle>
            <max_angle>2.35619449019</max_angle>
          </horizontal>
        </scan>
        <range>
          <min>0.1</min>
          <max>60.0</max>
          <resolution>0.01</resolution>
        </range>
        <noise>
          <type>gaussian</type>
          <mean>0.0</mean>
          <stddev>0.03</stddev>
        </noise>
      </ray>
      <plugin filename="libgazebo_ros_laser.so" name="gazebo_ros_rear_lrf_controller">
        <topicName>rear/scan</topicName>
        <frameName>rear_lrf_link</frameName>
      </plugin>
    </sensor>
  </gazebo>

</robot>