<?xml version="1.0" encoding="utf-8"?>

<robot xmlns:xacro="http://ros.org/wiki/xacro" name="horiokart">

  <xacro:macro name="horiokart_base" >
    <!-- =============== Link & Joint =============== -->
    <!-- Base -->
    <link name="base_footprint"/>

    <joint name="base_link_joint" type="fixed">
      <origin xyz="0 0 0.15" rpy="0 0 0"/>
      <parent link="base_footprint"/>
      <child link="base_link"/>
    </joint>
    <link name="base_link">
      <visual>
        <origin xyz="-0.2 0 0.1"/>
        <geometry>
          <box size="0.6 0.4 0.3"/>
        </geometry>
      </visual>
      <collision>
        <origin xyz="-0.2 0 0.1"/>
        <geometry>
          <box size="0.6 0.4 0.3"/>
        </geometry>
      </collision>
    </link>

    <joint name="right_wheel_joint" type="continuous">
      <axis xyz="0 0 1"/>
      <origin rpy="-1.5708 0 0" xyz="0 -0.25 0"/>
      <parent link="base_link"/>
      <child link="right_wheel_link"/>
    </joint>
    <link name="right_wheel_link">
      <visual>
        <geometry>
          <cylinder length="0.05" radius="0.15"/>
        </geometry>
      </visual>
      <collision>
        <geometry>
          <cylinder length="0.05" radius="0.15"/>
        </geometry>
      </collision>
    </link>

    <joint name="left_wheel_joint" type="continuous">
      <axis xyz="0 0 1"/>
      <origin rpy="-1.5708 0 0" xyz="0 0.25 0"/>
      <parent link="base_link"/>
      <child link="left_wheel_link"/>
    </joint>
    <link name="left_wheel_link">
      <visual>
        <geometry>
          <cylinder length="0.05" radius="0.15"/>
        </geometry>
      </visual>
      <collision>
        <geometry>
          <cylinder length="0.05" radius="0.15"/>
        </geometry>
      </collision>
    </link>

    <joint name="caster_joint" type="fixed">
      <origin rpy="0 0 0" xyz="-0.45 0 -0.1"/>
      <parent link="base_link"/>
      <child link="caster_link"/>
    </joint>
    <link name="caster_link">
      <visual>
        <geometry>
          <sphere radius="0.05"/>
        </geometry>
      </visual>
      <collision>
        <geometry>
          <sphere radius="0.05"/>
        </geometry>
      </collision>
    </link>

  </xacro:macro>

</robot>
